<?xml version="1.0" encoding="utf-8"?>
<!-- This URDF was automatically created by SolidWorks to URDF Exporter! Originally created by Stephen Brawner (brawner@gmail.com) 
     Commit Version: 1.6.0-1-g15f4949  Build Version: 1.6.7594.29634
     For more information, please see http://wiki.ros.org/sw_urdf_exporter -->
<robot
  name="my_robot">

  <gazebo reference="base_link">
    <material>Gazebo/Orange</material>
  </gazebo>
  <gazebo reference="Left_Link">
    <material>Gazebo/SkyBlue</material>
  </gazebo>
  <gazebo reference="Right_Link">
    <material>Gazebo/SkyBlue</material>
  </gazebo>
  <gazebo reference="Sensor_Laser">
    <material>Gazebo/SkyBlue</material>
  </gazebo>

  <link
    name="base_link">
    <inertial>
      <origin
        xyz="-0.001672 -1.1716E-17 0.050348"
        rpy="0 0 0" />
      <mass
        value="5" />
      <inertia
        ixx="0.33621"
        ixy="1.0274E-16"
        ixz="-0.0012409"
        iyy="0.7179"
        iyz="1.369E-17"
        izz="1.0147" />
    </inertial>
    <visual>
      <origin
        xyz="0 0 0"
        rpy="0 0 0" />
      <geometry>
        <mesh
          filename="package://auto_test/meshes/base_link.STL" />
      </geometry>
      <material
        name="">
        <color
          rgba="0.79216 0.81961 0.93333 1" />
      </material>
    </visual>
    <collision>
      <origin
        xyz="0 0 0"
        rpy="0 0 0" />
      <geometry>
        <mesh
          filename="package://auto_test/meshes/base_link.STL" />
      </geometry>
    </collision>
  </link>
  <link
    name="Left_Link">
    <inertial>
      <origin
        xyz="-0.01 0 -5.5511E-17"
        rpy="0 0 0" />
      <mass
        value="0.62204" />
      <inertia
        ixx="0.0031413"
        ixy="4.4128E-20"
        ixz="1.7802E-20"
        iyy="0.0015914"
        iyz="1.3553E-19"
        izz="0.0015914" />
    </inertial>
    <visual>
      <origin
        xyz="0 0 0"
        rpy="0 0 0" />
      <geometry>
        <mesh
          filename="package://auto_test/meshes/L_Link.STL" />
      </geometry>
      <material
        name="">
        <color
          rgba="0.79216 0.81961 0.93333 1" />
      </material>
    </visual>
    <collision>
      <origin
        xyz="0 0 0"
        rpy="0 0 0" />
      <geometry>
        <mesh
          filename="package://auto_test/meshes/L_Link.STL" />
      </geometry>
    </collision>
  </link>
  <joint
    name="Left_Joint"
    type="continuous">
    <origin
      xyz="-0.25 -0.2 0.05"
      rpy="1.7983 0 1.5708" />
    <parent
      link="base_link" />
    <child
      link="Left_Link" />
    <axis
      xyz="1 0 0" />
  </joint>
  <link
    name="Right_Link">
    <inertial>
      <origin
        xyz="0.01 0 -5.5511E-17"
        rpy="0 0 0" />
      <mass
        value="0.62204" />
      <inertia
        ixx="0.0031413"
        ixy="3.9891E-20"
        ixz="9.4367E-21"
        iyy="0.0015914"
        iyz="1.3553E-19"
        izz="0.0015914" />
    </inertial>
    <visual>
      <origin
        xyz="0 0 0"
        rpy="0 0 0" />
      <geometry>
        <mesh
          filename="package://auto_test/meshes/R_Link.STL" />
      </geometry>
      <material
        name="">
        <color
          rgba="0.79216 0.81961 0.93333 1" />
      </material>
    </visual>
    <collision>
      <origin
        xyz="0 0 0"
        rpy="0 0 0" />
      <geometry>
        <mesh
          filename="package://auto_test/meshes/R_Link.STL" />
      </geometry>
    </collision>
  </link>
  <joint
    name="Right_Joint"
    type="continuous">
    <origin
      xyz="-0.25 0.2 0.05"
      rpy="1.7983 0 1.5708" />
    <parent
      link="base_link" />
    <child
      link="Right_Link" />
    <axis
      xyz="1 0 0" />
  </joint>
  <link
    name="Castor_Link">
    <inertial>
      <origin
        xyz="7.043E-16 -7.3552E-16 5.2736E-16"
        rpy="0 0 0" />
      <mass
        value="0.5236" />
      <inertia
        ixx="0.0005236"
        ixy="-1.3553E-20"
        ixz="0"
        iyy="0.0005236"
        iyz="2.7105E-20"
        izz="0.0005236" />
    </inertial>
    <visual>
      <origin
        xyz="0 0 0"
        rpy="0 0 0" />
      <geometry>
        <mesh
          filename="package://auto_test/meshes/Castor_Link.STL" />
      </geometry>
      <material
        name="">
        <color
          rgba="0.79216 0.81961 0.93333 1" />
      </material>
    </visual>
    <collision>
      <origin
        xyz="0 0 0"
        rpy="0 0 0" />
      <geometry>
        <mesh
          filename="package://auto_test/meshes/Castor_Link.STL" />
      </geometry>
    </collision>
  </link>
  <joint
    name="Castor_Joint"
    type="continuous">
    <origin
      xyz="0.15 0 0"
      rpy="2.4146 -0.79692 -1.7817" />
    <parent
      link="base_link" />
    <child
      link="Castor_Link" />
    <axis
      xyz="0.68342 -0.62124 0.3834" />
    <dynamics
      damping="0"
      friction="0" />
  </joint>

  <link name="gripper_extension">
   <inertial>
      <mass value="0.5"/>
      <origin rpy="0 1.57075 0" xyz="0 0 0"/>
      <inertia ixx="0.00203125" ixy="0" ixz="0" iyy="0.00203125" iyz="0" izz="0.0003125"/>
    </inertial>
    <collision>
      <geometry>
        <cylinder length="0.15" radius="0.025"/>
      </geometry>
      <origin rpy="0 1.57075 0" xyz="0 0 0"/>
    </collision>
    <visual>
      <geometry>
        <cylinder length="0.15" radius="0.025"/>
      </geometry>
      <origin rpy="0 1.57075 0" xyz="0 0 0"/>
      <material name="white"/>
    </visual>
  </link>

  <joint name="base_to_gripper_extension" type="fixed">
    <parent link="base_link"/>
    <child link="gripper_extension"/>
    <origin xyz="0.375 0 0.05"/>
  </joint>

  <link name="gripper">
   <inertial>
      <mass value="1"/>
      <origin rpy="0 1.57075 0" xyz="0 0 0"/>
      <inertia ixx="0.00333333333333" ixy="0" ixz="0" iyy="0.0283333333333" iyz="0" izz="0.0283333333333"/>
    </inertial>
    <collision>
      <geometry>
        <box size="0.1 0.4 0.075"/>
      </geometry>
    </collision>
    <visual>
      <geometry>
        <box size="0.1 0.4 0.075"/>
      </geometry>
      <material name="blue"/>
    </visual>
  </link>
  <joint name="gripper_extension_to_gripper" type="fixed">
    <parent link="gripper_extension"/>
    <child link="gripper"/>
    <origin xyz="0.125 0 0"/>
  </joint> 
  <link name="gripper_left_hand">
   <inertial>
      <mass value="0.5"/>
      <origin rpy="0 1.57075 0" xyz="0 0 0"/>
      <inertia ixx="0.00270833333333" ixy="0" ixz="0" iyy="0.00104166666667" iyz="0" izz="0.00208333333333"/>
    </inertial>
    <collision>
      <geometry>
        <box size="0.15 0.05 0.075"/>
      </geometry>
    </collision>
    <visual>
      <geometry>
        <box size="0.15 0.05 0.075"/>
      </geometry>
      <material name="white"/>
    </visual>
  </link>
  <joint name="gripper_to_gripper_left_hand" type="prismatic">
    <parent link="gripper"/>
    <child link="gripper_left_hand"/>
    <limit effort="1000.0" lower="0.0" upper="0.05" velocity="0.1"/>
    <axis xyz="0 1 0"/>
    <origin xyz="0.125 -0.175 0"/>
  </joint>
  <link name="gripper_right_hand">
   <inertial>
      <mass value="0.5"/>
      <origin rpy="0 1.57075 0" xyz="0 0 0"/>
      <inertia ixx="0.00270833333333" ixy="0" ixz="0" iyy="0.00104166666667" iyz="0" izz="0.00208333333333"/>
    </inertial>
    <collision>
      <geometry>
        <box size="0.15 0.05 0.075"/>
      </geometry>
    </collision>
    <visual>
      <geometry>
        <box size="0.15 0.05 0.075"/>
      </geometry>
      <material name="white"/>
    </visual>
  </link>
  <joint name="gripper_to_gripper_right_hand" type="prismatic">
    <parent link="gripper"/>
    <child link="gripper_right_hand"/>
    <limit effort="1000.0" lower="-0.05" upper="0" velocity="0.1"/>
    <axis xyz="0 1 0"/>
    <origin xyz="0.125 0.175 0"/>
  </joint> 

  <link name="Sensor_Laser">
    <inertial>
      <origin xyz="0 0 0" rpy="0 0 0" />
      <mass value="1" />
      <inertia ixx="0.00145833333333" ixy="0" ixz="0" iyy="0.00145833333333" iyz="0" izz="0.00125"/>
    </inertial>

    <visual>
      <origin xyz="0 0 0" rpy="0 0 0" />
      <geometry>
        <cylinder radius="0.05" length="0.05"/>
      </geometry>
      <material name="white" />
    </visual>

    <collision>
      <origin xyz="0 0 0" rpy="0 0 0"/>
      <geometry>
        <cylinder radius="0.05" length="0.1"/>
      </geometry>
    </collision>
  </link>

  <joint name="joint_sensor_laser" type="fixed">
    <origin xyz="0.15 0 0.25" rpy="0 0 0"/>
    <parent link="base_link"/>
    <child link="Sensor_Laser"/>
  </joint>
    
    <link name="camera_link">
   <inertial>
      <mass value="0.5"/>
      <origin rpy="0 0 0" xyz="0 0 0"/>
      <inertia ixx="0.00270833333333" ixy="0" ixz="0" iyy="0.00104166666667" iyz="0" izz="0.00208333333333"/>
    </inertial>
    <collision>
      <geometry>
        <box size="0.1 0.1 0.1"/>
      </geometry>
    </collision>
    <visual>
      <geometry>
        <box size="0.1 0.1 0.1"/>
      </geometry>
      <material name="white"/>
    </visual>
  </link>

  <joint name="joint_sensor_camera" type="fixed">
    <origin xyz="0.15 0 0.15" rpy="0 0 0"/>
    <parent link="base_link"/>
    <child link="camera_link"/>
  </joint>

  <gazebo>
    <plugin filename="libgazebo_ros_diff_drive.so" name="differential_drive_controller">
      <alwaysOn>true</alwaysOn>
      <updateRate>20</updateRate>
      <leftJoint>Left_Joint</leftJoint>
      <rightJoint>Right_Joint</rightJoint>
      <wheelSeparation>0.4</wheelSeparation>
      <wheelDiameter>0.2</wheelDiameter>
      <torque>100</torque>
      <commandTopic>cmd_vel</commandTopic>
      <odometryTopic>odom</odometryTopic>
      <odometryFrame>odom</odometryFrame>
      <robotBaseFrame>base_link</robotBaseFrame>
    </plugin>
  </gazebo>

  <gazebo reference="Sensor_Laser">
    <sensor type="ray" name="head_hokuyo_sensor">
      <pose>0 0 0 0 0 0</pose>
      <visualize>false</visualize>
      <update_rate>20</update_rate>
      <ray>
        <scan>
          <horizontal>
            <samples>720</samples>
            <resolution>1</resolution>
            <min_angle>-1.570796</min_angle>
            <max_angle>1.570796</max_angle>
          </horizontal>
        </scan>
        <range>
          <min>0.10</min>
          <max>10.0</max>
          <resolution>0.01</resolution>
        </range>
        <noise>
          <type>gaussian</type>
          <mean>0.0</mean>
          <stddev>0.01</stddev>
        </noise>
      </ray>
      <plugin name="gazebo_ros_head_hokuyo_controller" filename="libgazebo_ros_laser.so">
        <topicName>/robot/laser/scan</topicName>
        <frameName>Sensor_Laser</frameName>
      </plugin>
    </sensor>
  </gazebo>

  <gazebo reference="camera_link">
    <sensor type="camera" name="camera1">
      <update_rate>30.0</update_rate>
      <camera name="head">
        <horizontal_fov>1.3962634</horizontal_fov>
        <image>
          <width>800</width>
          <height>800</height>
          <format>R8G8B8</format>
        </image>
        <clip>
          <near>0.02</near>
          <far>300</far>
        </clip>
        <noise>
          <type>gaussian</type>
          <!-- Noise is sampled independently per pixel on each frame.
               That pixel's noise value is added to each of its color
               channels, which at that point lie in the range [0,1]. -->
          <mean>0.0</mean>
          <stddev>0.007</stddev>
        </noise>
      </camera>
      <plugin name="camera_controller" filename="libgazebo_ros_camera.so">
        <alwaysOn>true</alwaysOn>
        <updateRate>0.0</updateRate>
        <cameraName>robot/camera1</cameraName>
        <imageTopicName>image_raw</imageTopicName>
        <cameraInfoTopicName>camera_info</cameraInfoTopicName>
        <frameName>camera_link</frameName>
        <hackBaseline>0.07</hackBaseline>
        <distortionK1>0.0</distortionK1>
        <distortionK2>0.0</distortionK2>
        <distortionK3>0.0</distortionK3>
        <distortionT1>0.0</distortionT1>
        <distortionT2>0.0</distortionT2>
      </plugin>
    </sensor>
  </gazebo>

</robot>
