<?xml version="1.0" encoding="utf-8"?>
<!-- This URDF was automatically created by SolidWorks to URDF Exporter! Originally created by Stephen Brawner (brawner@gmail.com) 
     Commit Version: 1.6.0-1-g15f4949  Build Version: 1.6.7594.29634
     For more information, please see http://wiki.ros.org/sw_urdf_exporter -->
<robot
  name="robot_assembly">
  <link
    name="base_link">
    <inertial>
      <origin
        xyz="-1.3863E-17 0.027637 0.030077"
        rpy="0 0 0" />
      <mass
        value="4" />
      <inertia
        ixx="0.56442"
        ixy="7.8489E-17"
        ixz="-4.1923E-18"
        iyy="0.34109"
        iyz="0.040266"
        izz="0.8599" />
    </inertial>
    <visual>
      <origin
        xyz="0 0 0"
        rpy="0 0 0" />
      <geometry>
        <mesh
          filename="package://robot_assembly/meshes/base_link.STL" />
      </geometry>
      <material
        name="">
        <color
          rgba="0.79216 0.81961 0.93333 1" />
      </material>
    </visual>
    <collision>
      <origin
        xyz="0 0 0"
        rpy="0 0 0" />
      <geometry>
        <mesh
          filename="package://robot_assembly/meshes/base_link.STL" />
      </geometry>
    </collision>
  </link>
  <link
    name="Right_wheel_Link">
    <inertial>
      <origin
        xyz="0.024841 -1.2351E-15 1.7528E-14"
        rpy="0 0 0" />
      <mass
        value="1.0395" />
      <inertia
        ixx="0.010857"
        ixy="5.2158E-20"
        ixz="-2.9389E-18"
        iyy="0.0055922"
        iyz="1.0842E-18"
        izz="0.0055922" />
    </inertial>
    <visual>
      <origin
        xyz="0 0 0"
        rpy="0 0 0" />
      <geometry>
        <mesh
          filename="package://robot_assembly/meshes/Right_wheel_Link.STL" />
      </geometry>
      <material
        name="">
        <color
          rgba="0.79216 0.81961 0.93333 1" />
      </material>
    </visual>
    <collision>
      <origin
        xyz="0 0 0"
        rpy="0 0 0" />
      <geometry>
        <mesh
          filename="package://robot_assembly/meshes/Right_wheel_Link.STL" />
      </geometry>
    </collision>
  </link>
  <joint
    name="Right_wheel_joint"
    type="continuous">
    <origin
      xyz="0.235 -0.1 0.04"
      rpy="0.97451 0 0" />
    <parent
      link="base_link" />
    <child
      link="Right_wheel_Link" />
    <axis
      xyz="-1 0 0" />
  </joint>
  <link
    name="Left_wheel_Link">
    <inertial>
      <origin
        xyz="0.024841 -1.1519E-15 1.7542E-14"
        rpy="0 0 0" />
      <mass
        value="1.0395" />
      <inertia
        ixx="0.010857"
        ixy="-3.2167E-19"
        ixz="-1.9974E-18"
        iyy="0.0055922"
        iyz="-2.1684E-19"
        izz="0.0055922" />
    </inertial>
    <visual>
      <origin
        xyz="0 0 0"
        rpy="0 0 0" />
      <geometry>
        <mesh
          filename="package://robot_assembly/meshes/Left_wheel_Link.STL" />
      </geometry>
      <material
        name="">
        <color
          rgba="0.79216 0.81961 0.93333 1" />
      </material>
    </visual>
    <collision>
      <origin
        xyz="0 0 0"
        rpy="0 0 0" />
      <geometry>
        <mesh
          filename="package://robot_assembly/meshes/Left_wheel_Link.STL" />
      </geometry>
    </collision>
  </link>
  <joint
    name="Left_wheel_joint"
    type="continuous">
    <origin
      xyz="-0.235 -0.1 0.04"
      rpy="1.6761 0 3.1416" />
    <parent
      link="base_link" />
    <child
      link="Left_wheel_Link" />
    <axis
      xyz="1 0 0" />
  </joint>
  <gazebo>
    <plugin filename="libgazebo_ros_diff_drive.so" name="differential_drive_controller">
      <alwaysOn>true</alwaysOn>
      <updateRate>20</updateRate>
      <leftJoint>Left_wheel_joint</leftJoint>
      <rightJoint>Right_wheel_joint</rightJoint>
      <wheelSeparation>0.470</wheelSeparation>
      <wheelDiameter>0.25</wheelDiameter>
      <torque>0.1</torque>
      <commandTopic>cmd_vel</commandTopic>
      <odometryTopic>odom</odometryTopic>
      <odometryFrame>odom</odometryFrame>
      <robotBaseFrame>base_link</robotBaseFrame>
    </plugin>
  </gazebo>
</robot>
